2024-03-23 12:10:13,948 AutoFE.py:30 __init__ INFO | Namespace(cuda='0', epochs=100, ppo_epochs=20, episodes=3, file_name='SPECTF', mode='classify', model='rf', metric='f1', seed=1, train_size=0.7, cv=5, shuffle=False, d_model=128, d_k=32, d_v=32, d_ff=64, n_heads=6, worker=1, steps_num=3, lr=0.0001, entropy_weight=0.0001, baseline_weight=0.95, gama=0.9, gae_lambda=0.95, batch_size=4, c_columns=['V0', 'V1', 'V2', 'V3', 'V4', 'V5', 'V6', 'V7', 'V8', 'V9', 'V10', 'V11', 'V12', 'V13', 'V14', 'V15', 'V16', 'V17', 'V18', 'V19', 'V20', 'V21', 'V22', 'V23', 'V24', 'V25', 'V26', 'V27', 'V28', 'V29', 'V30', 'V31', 'V32', 'V33', 'V34', 'V35', 'V36', 'V37', 'V38', 'V39', 'V40', 'V41', 'V42', 'V43'], d_columns=[], target='label')
2024-03-23 12:10:13,948 AutoFE.py:31 __init__ INFO | File name: SPECTF
2024-03-23 12:10:13,948 AutoFE.py:32 __init__ INFO | Data shape: (267, 45)
2024-03-23 12:10:14,428 AutoFE.py:85 set_cuda INFO | Use device: 0, cuda:0, NVIDIA GeForce RTX 4060 Laptop GPU
2024-03-23 12:10:14,428 AutoFE.py:75 __init__ INFO | Done AutoFE initialization.
2024-03-23 12:10:14,623 AutoFE.py:98 fit_attention INFO | score_b=0.8277428371767994, scores_b=[0.7962963  0.85185185 0.88679245 0.71698113 0.88679245]
2024-03-23 12:10:33,134 main_ppo.py:80 <module> INFO | Traceback (most recent call last):
  File "D:\python files\pythonProject3\PPO_transformer_lstm1\main_ppo.py", line 76, in <module>
    autofe.fit_attention(args)
  File "D:\python files\pythonProject3\PPO_transformer_lstm1\AutoFE.py", line 144, in fit_attention
    w_c = sample(args, self.ppo, pipline_args_train, df_c_encode, df_d_encode, df_t_norm, c_ops,d_ops,epoch, i, self.device)
  File "D:\python files\pythonProject3\PPO_transformer_lstm1\feature_engineer\training_ops.py", line 51, in sample
    df_c_encode, df_d_encode = pipline_ff.process_data(fe)
  File "D:\python files\pythonProject3\PPO_transformer_lstm1\process_data\update_data.py", line 26, in process_data
    self.single_fe_operations()
  File "D:\python files\pythonProject3\PPO_transformer_lstm1\process_data\update_data.py", line 104, in single_fe_operations
    new_fe = globals()[operation[0]](ori_col.values)
KeyError: 5

2024-03-23 12:10:33,708 main_ppo.py:82 <module> INFO | Total cost time: 19.4575 s.
