2023-10-26 09:53:23,835 autofe.py:51 __init__ INFO | Namespace(cuda='0', train_size=0.7, epochs=300, ppo_epochs=30, episodes=24, lr=0.0001, entropy_weight=0.0001, baseline_weight=0.95, gama=0.9, gae_lambda=0.95, batch_size=4, d_model=128, d_k=32, d_v=32, d_ff=64, n_heads=6, worker=8, steps_num=3, combine=True, preprocess=True, seed=1, cv=5, cv_train_size=0.7, cv_seed=1, split_train_test=False, shuffle=False, enc_c_pth='', enc_d_pth='', mode='classify', model='xgb', metric='f1', file_name='SPECTF', c_columns=['V0', 'V1', 'V2', 'V3', 'V4', 'V5', 'V6', 'V7', 'V8', 'V9', 'V10', 'V11', 'V12', 'V13', 'V14', 'V15', 'V16', 'V17', 'V18', 'V19', 'V20', 'V21', 'V22', 'V23', 'V24', 'V25', 'V26', 'V27', 'V28', 'V29', 'V30', 'V31', 'V32', 'V33', 'V34', 'V35', 'V36', 'V37', 'V38', 'V39', 'V40', 'V41', 'V42', 'V43'], d_columns=[], target='label')
2023-10-26 09:53:23,835 autofe.py:52 __init__ INFO | File name: SPECTF
2023-10-26 09:53:23,835 autofe.py:53 __init__ INFO | Data shape: (267, 45)
2023-10-26 09:53:24,319 autofe.py:120 set_cuda INFO | Use device: 0, cuda:0, NVIDIA GeForce RTX 4060 Laptop GPU
2023-10-26 09:53:24,319 autofe.py:110 __init__ INFO | Done AutoFE initialization.
2023-10-26 09:53:24,337 autofe.py:429 _get_cv_baseline INFO | Start getting CV baseline...
2023-10-26 09:53:24,337 autofe.py:446 _get_cv_baseline INFO | CV split end. Start CV scoring...
2023-10-26 09:53:24,375 autofe.py:477 _get_cv_baseline INFO | no encoding
2023-10-26 09:53:24,375 autofe.py:488 _get_cv_baseline INFO | Start training model...
2023-10-26 09:53:24,432 autofe.py:477 _get_cv_baseline INFO | no encoding
2023-10-26 09:53:24,432 autofe.py:488 _get_cv_baseline INFO | Start training model...
2023-10-26 09:53:24,496 autofe.py:477 _get_cv_baseline INFO | no encoding
2023-10-26 09:53:24,496 autofe.py:488 _get_cv_baseline INFO | Start training model...
2023-10-26 09:53:24,571 autofe.py:477 _get_cv_baseline INFO | no encoding
2023-10-26 09:53:24,571 autofe.py:488 _get_cv_baseline INFO | Start training model...
2023-10-26 09:53:24,653 autofe.py:477 _get_cv_baseline INFO | no encoding
2023-10-26 09:53:24,653 autofe.py:488 _get_cv_baseline INFO | Start training model...
2023-10-26 09:53:24,668 autofe.py:140 fit_attention INFO | score_b=0.8015399999999999, scores_b=[0.8148, 0.7778, 0.7547, 0.8113, 0.8491]
2023-10-26 09:53:24,722 model_rl.py:14 __init__ INFO | Randomly initial encoder
2023-10-26 09:53:24,773 model_rl.py:14 __init__ INFO | Randomly initial encoder
2023-10-26 09:53:33,416 main_attention.py:91 <module> INFO | multiprocessing.pool.RemoteTraceback: 
"""
Traceback (most recent call last):
  File "D:\software\anaconda\envs\pytorch\lib\site-packages\pandas\core\frame.py", line 4243, in _ensure_valid_index
    value = Series(value)
  File "D:\software\anaconda\envs\pytorch\lib\site-packages\pandas\core\series.py", line 470, in __init__
    data = sanitize_array(data, index, dtype, copy)
  File "D:\software\anaconda\envs\pytorch\lib\site-packages\pandas\core\construction.py", line 647, in sanitize_array
    subarr = _sanitize_ndim(subarr, data, dtype, index, allow_2d=allow_2d)
  File "D:\software\anaconda\envs\pytorch\lib\site-packages\pandas\core\construction.py", line 698, in _sanitize_ndim
    raise ValueError("Data must be 1-dimensional")
ValueError: Data must be 1-dimensional

The above exception was the direct cause of the following exception:

Traceback (most recent call last):
  File "D:\software\anaconda\envs\pytorch\lib\multiprocessing\pool.py", line 125, in worker
    result = (True, func(*args, **kwds))
  File "D:\python files\pythonProject3\FETCH\feature_engineer\attention_searching\training_ops.py", line 149, in apply_actions
    x_c_encode, x_c_combine = pipline_ff_c.process_continuous(fe_c)
  File "D:\python files\pythonProject3\FETCH\process_data\feature_pipeline.py", line 359, in process_continuous
    self.arithmetic_operations()
  File "D:\python files\pythonProject3\FETCH\process_data\feature_pipeline.py", line 225, in arithmetic_operations
    if not self.isvalid: Candidate_features[name] = new_fe
  File "D:\software\anaconda\envs\pytorch\lib\site-packages\pandas\core\frame.py", line 3980, in __setitem__
    self._set_item(key, value)
  File "D:\software\anaconda\envs\pytorch\lib\site-packages\pandas\core\frame.py", line 4174, in _set_item
    value = self._sanitize_column(value)
  File "D:\software\anaconda\envs\pytorch\lib\site-packages\pandas\core\frame.py", line 4905, in _sanitize_column
    self._ensure_valid_index(value)
  File "D:\software\anaconda\envs\pytorch\lib\site-packages\pandas\core\frame.py", line 4245, in _ensure_valid_index
    raise ValueError(
ValueError: Cannot set a frame with no defined index and a value that cannot be converted to a Series
"""

The above exception was the direct cause of the following exception:

Traceback (most recent call last):
  File "D:\python files\pythonProject3\FETCH\main_attention.py", line 88, in <module>
    autofe.fit_attention(args)
  File "D:\python files\pythonProject3\FETCH\autofe.py", line 272, in fit_attention
    ret = p.get()
  File "D:\software\anaconda\envs\pytorch\lib\multiprocessing\pool.py", line 774, in get
    raise self._value
ValueError: Cannot set a frame with no defined index and a value that cannot be converted to a Series

2023-10-26 09:53:33,417 main_attention.py:93 <module> INFO | Total cost time: 9.5828 s.
2023-10-26 09:53:53,525 autofe.py:51 __init__ INFO | Namespace(cuda='0', train_size=0.7, epochs=300, ppo_epochs=30, episodes=24, lr=0.0001, entropy_weight=0.0001, baseline_weight=0.95, gama=0.9, gae_lambda=0.95, batch_size=4, d_model=128, d_k=32, d_v=32, d_ff=64, n_heads=6, worker=2, steps_num=3, combine=True, preprocess=True, seed=1, cv=5, cv_train_size=0.7, cv_seed=1, split_train_test=False, shuffle=False, enc_c_pth='', enc_d_pth='', mode='classify', model='xgb', metric='f1', file_name='SPECTF', c_columns=['V0', 'V1', 'V2', 'V3', 'V4', 'V5', 'V6', 'V7', 'V8', 'V9', 'V10', 'V11', 'V12', 'V13', 'V14', 'V15', 'V16', 'V17', 'V18', 'V19', 'V20', 'V21', 'V22', 'V23', 'V24', 'V25', 'V26', 'V27', 'V28', 'V29', 'V30', 'V31', 'V32', 'V33', 'V34', 'V35', 'V36', 'V37', 'V38', 'V39', 'V40', 'V41', 'V42', 'V43'], d_columns=[], target='label')
2023-10-26 09:53:53,525 autofe.py:52 __init__ INFO | File name: SPECTF
2023-10-26 09:53:53,526 autofe.py:53 __init__ INFO | Data shape: (267, 45)
2023-10-26 09:53:55,059 autofe.py:120 set_cuda INFO | Use device: 0, cuda:0, NVIDIA GeForce RTX 4060 Laptop GPU
2023-10-26 09:53:55,059 autofe.py:110 __init__ INFO | Done AutoFE initialization.
2023-10-26 09:53:55,068 autofe.py:429 _get_cv_baseline INFO | Start getting CV baseline...
2023-10-26 09:53:55,068 autofe.py:446 _get_cv_baseline INFO | CV split end. Start CV scoring...
2023-10-26 09:53:55,106 autofe.py:477 _get_cv_baseline INFO | no encoding
2023-10-26 09:53:55,106 autofe.py:488 _get_cv_baseline INFO | Start training model...
2023-10-26 09:53:55,151 autofe.py:477 _get_cv_baseline INFO | no encoding
2023-10-26 09:53:55,151 autofe.py:488 _get_cv_baseline INFO | Start training model...
2023-10-26 09:53:55,198 autofe.py:477 _get_cv_baseline INFO | no encoding
2023-10-26 09:53:55,198 autofe.py:488 _get_cv_baseline INFO | Start training model...
2023-10-26 09:53:55,244 autofe.py:477 _get_cv_baseline INFO | no encoding
2023-10-26 09:53:55,244 autofe.py:488 _get_cv_baseline INFO | Start training model...
2023-10-26 09:53:55,302 autofe.py:477 _get_cv_baseline INFO | no encoding
2023-10-26 09:53:55,302 autofe.py:488 _get_cv_baseline INFO | Start training model...
2023-10-26 09:53:55,315 autofe.py:140 fit_attention INFO | score_b=0.8015399999999999, scores_b=[0.8148, 0.7778, 0.7547, 0.8113, 0.8491]
2023-10-26 09:53:55,360 model_rl.py:14 __init__ INFO | Randomly initial encoder
2023-10-26 09:53:55,406 model_rl.py:14 __init__ INFO | Randomly initial encoder
2023-10-26 09:54:00,322 main_attention.py:91 <module> INFO | multiprocessing.pool.RemoteTraceback: 
"""
Traceback (most recent call last):
  File "D:\software\anaconda\envs\pytorch\lib\site-packages\pandas\core\frame.py", line 4243, in _ensure_valid_index
    value = Series(value)
  File "D:\software\anaconda\envs\pytorch\lib\site-packages\pandas\core\series.py", line 470, in __init__
    data = sanitize_array(data, index, dtype, copy)
  File "D:\software\anaconda\envs\pytorch\lib\site-packages\pandas\core\construction.py", line 647, in sanitize_array
    subarr = _sanitize_ndim(subarr, data, dtype, index, allow_2d=allow_2d)
  File "D:\software\anaconda\envs\pytorch\lib\site-packages\pandas\core\construction.py", line 698, in _sanitize_ndim
    raise ValueError("Data must be 1-dimensional")
ValueError: Data must be 1-dimensional

The above exception was the direct cause of the following exception:

Traceback (most recent call last):
  File "D:\software\anaconda\envs\pytorch\lib\multiprocessing\pool.py", line 125, in worker
    result = (True, func(*args, **kwds))
  File "D:\python files\pythonProject3\FETCH\feature_engineer\attention_searching\training_ops.py", line 149, in apply_actions
    x_c_encode, x_c_combine = pipline_ff_c.process_continuous(fe_c)
  File "D:\python files\pythonProject3\FETCH\process_data\feature_pipeline.py", line 359, in process_continuous
    self.arithmetic_operations()
  File "D:\python files\pythonProject3\FETCH\process_data\feature_pipeline.py", line 225, in arithmetic_operations
    if not self.isvalid: Candidate_features[name] = new_fe
  File "D:\software\anaconda\envs\pytorch\lib\site-packages\pandas\core\frame.py", line 3980, in __setitem__
    self._set_item(key, value)
  File "D:\software\anaconda\envs\pytorch\lib\site-packages\pandas\core\frame.py", line 4174, in _set_item
    value = self._sanitize_column(value)
  File "D:\software\anaconda\envs\pytorch\lib\site-packages\pandas\core\frame.py", line 4905, in _sanitize_column
    self._ensure_valid_index(value)
  File "D:\software\anaconda\envs\pytorch\lib\site-packages\pandas\core\frame.py", line 4245, in _ensure_valid_index
    raise ValueError(
ValueError: Cannot set a frame with no defined index and a value that cannot be converted to a Series
"""

The above exception was the direct cause of the following exception:

Traceback (most recent call last):
  File "D:\python files\pythonProject3\FETCH\main_attention.py", line 88, in <module>
    autofe.fit_attention(args)
  File "D:\python files\pythonProject3\FETCH\autofe.py", line 272, in fit_attention
    ret = p.get()
  File "D:\software\anaconda\envs\pytorch\lib\multiprocessing\pool.py", line 774, in get
    raise self._value
ValueError: Cannot set a frame with no defined index and a value that cannot be converted to a Series

2023-10-26 09:54:00,322 main_attention.py:93 <module> INFO | Total cost time: 6.7971 s.
