2024-03-13 14:15:42,466 AutoFE.py:35 __init__ INFO | Namespace(cuda='0', epochs=100, ppo_epochs=20, episodes=4, file_name='hepatitis', mode='classify', model='rf', metric='f1', seed=1, train_size=0.7, cv=5, shuffle=False, d_model=128, d_k=32, d_v=32, d_ff=64, n_heads=6, worker=1, steps_num=5, lr=0.0001, entropy_weight=0.0001, baseline_weight=0.95, gama=0.9, gae_lambda=0.95, batch_size=4, c_columns=['V0', 'V13', 'V14', 'V15', 'V16', 'V17'], d_columns=['V1', 'V2', 'V3', 'V4', 'V5', 'V6', 'V7', 'V8', 'V9', 'V10', 'V11', 'V12', 'V18'], target='label')
2024-03-13 14:15:42,467 AutoFE.py:36 __init__ INFO | File name: hepatitis
2024-03-13 14:15:42,467 AutoFE.py:37 __init__ INFO | Data shape: (155, 20)
2024-03-13 14:15:43,987 AutoFE.py:90 set_cuda INFO | Use device: 0, cuda:0, NVIDIA GeForce RTX 4060 Laptop GPU
2024-03-13 14:15:43,988 AutoFE.py:80 __init__ INFO | Done AutoFE initialization.
2024-03-13 14:15:44,042 AutoFE.py:103 fit_attention INFO | score_b=0.8129032258064516, scores_b=[0.80645161 0.80645161 0.87096774 0.70967742 0.87096774]
2024-03-13 14:15:45,395 main_ppo.py:80 <module> INFO | Traceback (most recent call last):
  File "D:\software\anaconda\envs\pytorch\lib\site-packages\pandas\core\indexes\base.py", line 3802, in get_loc
    return self._engine.get_loc(casted_key)
  File "pandas\_libs\index.pyx", line 138, in pandas._libs.index.IndexEngine.get_loc
  File "pandas\_libs\index.pyx", line 144, in pandas._libs.index.IndexEngine.get_loc
TypeError: '(slice(None, None, None), 13)' is an invalid key

During handling of the above exception, another exception occurred:

Traceback (most recent call last):
  File "D:\python files\pythonProject3\PPO_transformer_lstm\main_ppo.py", line 76, in <module>
    autofe.fit_attention(args)
  File "D:\python files\pythonProject3\PPO_transformer_lstm\AutoFE.py", line 146, in fit_attention
    w_c = sample(args, self.ppo, pipline_args_train, df_c_encode, df_d_encode, df_t_norm, c_ops,d_ops,epoch, i, self.device)
  File "D:\python files\pythonProject3\PPO_transformer_lstm\feature_engineer\training_ops.py", line 44, in sample
    df_c_encode, df_d_encode = pipline_ff.process_data(fe)
  File "D:\python files\pythonProject3\PPO_transformer_lstm\process_data\pipeline_data.py", line 62, in process_data
    self.feature_combine()
  File "D:\python files\pythonProject3\PPO_transformer_lstm\process_data\pipeline_data.py", line 151, in feature_combine
    ori_fe2 = self.ori_cols_combine[:,actions[1]]
  File "D:\software\anaconda\envs\pytorch\lib\site-packages\pandas\core\frame.py", line 3807, in __getitem__
    indexer = self.columns.get_loc(key)
  File "D:\software\anaconda\envs\pytorch\lib\site-packages\pandas\core\indexes\base.py", line 3809, in get_loc
    self._check_indexing_error(key)
  File "D:\software\anaconda\envs\pytorch\lib\site-packages\pandas\core\indexes\base.py", line 5925, in _check_indexing_error
    raise InvalidIndexError(key)
pandas.errors.InvalidIndexError: (slice(None, None, None), 13)

2024-03-13 14:15:45,396 main_ppo.py:82 <module> INFO | Total cost time: 2.9314 s.
