2024-03-13 09:35:23,005 AutoFE.py:35 __init__ INFO | Namespace(cuda='0', epochs=100, ppo_epochs=20, episodes=4, file_name='hepatitis', mode='classify', model='rf', metric='f1', seed=1, train_size=0.7, cv=5, shuffle=False, d_model=128, d_k=32, d_v=32, d_ff=64, n_heads=6, worker=1, steps_num=5, lr=0.0001, entropy_weight=0.0001, baseline_weight=0.95, gama=0.9, gae_lambda=0.95, batch_size=4, c_columns=['V0', 'V13', 'V14', 'V15', 'V16', 'V17'], d_columns=['V1', 'V2', 'V3', 'V4', 'V5', 'V6', 'V7', 'V8', 'V9', 'V10', 'V11', 'V12', 'V18'], target='label')
2024-03-13 09:35:23,005 AutoFE.py:36 __init__ INFO | File name: hepatitis
2024-03-13 09:35:23,005 AutoFE.py:37 __init__ INFO | Data shape: (155, 20)
2024-03-13 09:35:24,524 AutoFE.py:90 set_cuda INFO | Use device: 0, cuda:0, NVIDIA GeForce RTX 4060 Laptop GPU
2024-03-13 09:35:24,530 AutoFE.py:80 __init__ INFO | Done AutoFE initialization.
2024-03-13 09:35:24,651 AutoFE.py:103 fit_attention INFO | score_b=0.8129032258064516, scores_b=[0.80645161 0.80645161 0.87096774 0.70967742 0.87096774]
2024-03-13 09:37:37,994 main_ppo.py:80 <module> INFO | Traceback (most recent call last):
  File "D:\python files\pythonProject3\PPO_transformer_lstm\main_ppo.py", line 76, in <module>
    autofe.fit_attention(args)
  File "D:\python files\pythonProject3\PPO_transformer_lstm\AutoFE.py", line 146, in fit_attention
    w_c = sample(args, self.ppo, pipline_args_train, df_c_encode, df_d_encode, df_t_norm, c_ops,d_ops,epoch, i, self.device)
  File "D:\python files\pythonProject3\PPO_transformer_lstm\feature_engineer\training_ops.py", line 44, in sample
    df_c_encode, df_d_encode = pipline_ff.process_data(fe)
  File "D:\python files\pythonProject3\PPO_transformer_lstm\process_data\pipeline_data.py", line 68, in process_data
    self.feature_combine()
  File "D:\python files\pythonProject3\PPO_transformer_lstm\process_data\pipeline_data.py", line 157, in feature_combine
    ori_fe2 = self.combine.iloc[:, actions[1]]
  File "D:\software\anaconda\envs\pytorch\lib\site-packages\pandas\core\indexing.py", line 1067, in __getitem__
    return self._getitem_tuple(key)
  File "D:\software\anaconda\envs\pytorch\lib\site-packages\pandas\core\indexing.py", line 1563, in _getitem_tuple
    tup = self._validate_tuple_indexer(tup)
  File "D:\software\anaconda\envs\pytorch\lib\site-packages\pandas\core\indexing.py", line 873, in _validate_tuple_indexer
    self._validate_key(k, i)
  File "D:\software\anaconda\envs\pytorch\lib\site-packages\pandas\core\indexing.py", line 1466, in _validate_key
    self._validate_integer(key, axis)
  File "D:\software\anaconda\envs\pytorch\lib\site-packages\pandas\core\indexing.py", line 1557, in _validate_integer
    raise IndexError("single positional indexer is out-of-bounds")
IndexError: single positional indexer is out-of-bounds

2024-03-13 09:37:39,206 main_ppo.py:82 <module> INFO | Total cost time: 135.459 s.
